!SESSION 2015-06-07 18:01:55.891 -----------------------------------------------
eclipse.buildId=4.4.1.M20140925-0400
java.version=1.7.0_55
java.vendor=Oracle Corporation
BootLoader constants: OS=linux, ARCH=x86_64, WS=gtk, NL=pl_PL
Framework arguments:  -product org.eclipse.epp.package.standard.product
Command-line arguments:  -os linux -ws gtk -arch x86_64 -product org.eclipse.epp.package.standard.product

This is a continuation of log file /home/user/python_project/python_web_analizer/.metadata/.bak_0.log
Created Time: 2015-06-07 23:07:10.551

!ENTRY org.python.pydev.debug 4 4 2015-06-07 23:07:10.551
!MESSAGE Error fetching a variable
!STACK 1
org.eclipse.core.runtime.CoreException: pydevd error:Error evaluating expression Traceback (most recent call last):
  File "/home/user/.eclipse/org.eclipse.platform_4.4.1_1773823767_linux_gtk_x86_64/plugins/org.python.pydev_4.1.0.201505270003/pysrc/pydevd_comm.py", line 1069, in doIt
    result = pydevd_vars.evaluateExpression(self.thread_id, self.frame_id, self.expression, self.doExec)
  File "/home/user/.eclipse/org.eclipse.platform_4.4.1_1773823767_linux_gtk_x86_64/plugins/org.python.pydev_4.1.0.201505270003/pysrc/pydevd_vars.py", line 333, in evaluateExpression
    expression = str(expression.replace('@LINE@', '\n'))
UnicodeEncodeError: 'ascii' codec can't encode character u'\u0142' in position 10: ordinal not in range(128)

	at org.python.pydev.debug.model.remote.EvaluateExpressionCommand.getResponse(EvaluateExpressionCommand.java:76)
	at org.python.pydev.debug.model.PyWatchExpressionDelegate.commandComplete(PyWatchExpressionDelegate.java:118)
	at org.python.pydev.debug.model.remote.AbstractDebuggerCommand.processResponse(AbstractDebuggerCommand.java:147)
	at org.python.pydev.debug.model.remote.DebuggerReader.processCommand(DebuggerReader.java:118)
	at org.python.pydev.debug.model.remote.DebuggerReader.run(DebuggerReader.java:140)
	at java.lang.Thread.run(Thread.java:745)
!SUBENTRY 1 org.python.pydev.debug 4 4 2015-06-07 23:07:10.552
!MESSAGE pydevd error:Error evaluating expression Traceback (most recent call last):
  File "/home/user/.eclipse/org.eclipse.platform_4.4.1_1773823767_linux_gtk_x86_64/plugins/org.python.pydev_4.1.0.201505270003/pysrc/pydevd_comm.py", line 1069, in doIt
    result = pydevd_vars.evaluateExpression(self.thread_id, self.frame_id, self.expression, self.doExec)
  File "/home/user/.eclipse/org.eclipse.platform_4.4.1_1773823767_linux_gtk_x86_64/plugins/org.python.pydev_4.1.0.201505270003/pysrc/pydevd_vars.py", line 333, in evaluateExpression
    expression = str(expression.replace('@LINE@', '\n'))
UnicodeEncodeError: 'ascii' codec can't encode character u'\u0142' in position 10: ordinal not in range(128)


!ENTRY org.python.pydev.debug 4 4 2015-06-07 23:07:10.609
!MESSAGE Error fetching a variable
!STACK 1
org.eclipse.core.runtime.CoreException: pydevd error:Error evaluating expression Traceback (most recent call last):
  File "/home/user/.eclipse/org.eclipse.platform_4.4.1_1773823767_linux_gtk_x86_64/plugins/org.python.pydev_4.1.0.201505270003/pysrc/pydevd_comm.py", line 1069, in doIt
    result = pydevd_vars.evaluateExpression(self.thread_id, self.frame_id, self.expression, self.doExec)
  File "/home/user/.eclipse/org.eclipse.platform_4.4.1_1773823767_linux_gtk_x86_64/plugins/org.python.pydev_4.1.0.201505270003/pysrc/pydevd_vars.py", line 333, in evaluateExpression
    expression = str(expression.replace('@LINE@', '\n'))
UnicodeEncodeError: 'ascii' codec can't encode character u'\u0142' in position 10: ordinal not in range(128)

	at org.python.pydev.debug.model.remote.EvaluateExpressionCommand.getResponse(EvaluateExpressionCommand.java:76)
	at org.python.pydev.debug.model.PyWatchExpressionDelegate.commandComplete(PyWatchExpressionDelegate.java:118)
	at org.python.pydev.debug.model.remote.AbstractDebuggerCommand.processResponse(AbstractDebuggerCommand.java:147)
	at org.python.pydev.debug.model.remote.DebuggerReader.processCommand(DebuggerReader.java:118)
	at org.python.pydev.debug.model.remote.DebuggerReader.run(DebuggerReader.java:140)
	at java.lang.Thread.run(Thread.java:745)
!SUBENTRY 1 org.python.pydev.debug 4 4 2015-06-07 23:07:10.609
!MESSAGE pydevd error:Error evaluating expression Traceback (most recent call last):
  File "/home/user/.eclipse/org.eclipse.platform_4.4.1_1773823767_linux_gtk_x86_64/plugins/org.python.pydev_4.1.0.201505270003/pysrc/pydevd_comm.py", line 1069, in doIt
    result = pydevd_vars.evaluateExpression(self.thread_id, self.frame_id, self.expression, self.doExec)
  File "/home/user/.eclipse/org.eclipse.platform_4.4.1_1773823767_linux_gtk_x86_64/plugins/org.python.pydev_4.1.0.201505270003/pysrc/pydevd_vars.py", line 333, in evaluateExpression
    expression = str(expression.replace('@LINE@', '\n'))
UnicodeEncodeError: 'ascii' codec can't encode character u'\u0142' in position 10: ordinal not in range(128)


!ENTRY org.python.pydev.debug 4 4 2015-06-07 23:07:22.024
!MESSAGE Error fetching a variable
!STACK 1
org.eclipse.core.runtime.CoreException: pydevd error:Error evaluating expression Traceback (most recent call last):
  File "/home/user/.eclipse/org.eclipse.platform_4.4.1_1773823767_linux_gtk_x86_64/plugins/org.python.pydev_4.1.0.201505270003/pysrc/pydevd_comm.py", line 1069, in doIt
    result = pydevd_vars.evaluateExpression(self.thread_id, self.frame_id, self.expression, self.doExec)
  File "/home/user/.eclipse/org.eclipse.platform_4.4.1_1773823767_linux_gtk_x86_64/plugins/org.python.pydev_4.1.0.201505270003/pysrc/pydevd_vars.py", line 333, in evaluateExpression
    expression = str(expression.replace('@LINE@', '\n'))
UnicodeEncodeError: 'ascii' codec can't encode character u'\u0142' in position 10: ordinal not in range(128)

	at org.python.pydev.debug.model.remote.EvaluateExpressionCommand.getResponse(EvaluateExpressionCommand.java:76)
	at org.python.pydev.debug.model.PyWatchExpressionDelegate.commandComplete(PyWatchExpressionDelegate.java:118)
	at org.python.pydev.debug.model.remote.AbstractDebuggerCommand.processResponse(AbstractDebuggerCommand.java:147)
	at org.python.pydev.debug.model.remote.DebuggerReader.processCommand(DebuggerReader.java:118)
	at org.python.pydev.debug.model.remote.DebuggerReader.run(DebuggerReader.java:140)
	at java.lang.Thread.run(Thread.java:745)
!SUBENTRY 1 org.python.pydev.debug 4 4 2015-06-07 23:07:22.025
!MESSAGE pydevd error:Error evaluating expression Traceback (most recent call last):
  File "/home/user/.eclipse/org.eclipse.platform_4.4.1_1773823767_linux_gtk_x86_64/plugins/org.python.pydev_4.1.0.201505270003/pysrc/pydevd_comm.py", line 1069, in doIt
    result = pydevd_vars.evaluateExpression(self.thread_id, self.frame_id, self.expression, self.doExec)
  File "/home/user/.eclipse/org.eclipse.platform_4.4.1_1773823767_linux_gtk_x86_64/plugins/org.python.pydev_4.1.0.201505270003/pysrc/pydevd_vars.py", line 333, in evaluateExpression
    expression = str(expression.replace('@LINE@', '\n'))
UnicodeEncodeError: 'ascii' codec can't encode character u'\u0142' in position 10: ordinal not in range(128)


!ENTRY org.python.pydev.shared_core 4 4 2015-06-08 01:23:07.118
!MESSAGE /usr/lib/python2.7/site-packages/logilab
!STACK 0
java.nio.file.AccessDeniedException: /usr/lib/python2.7/site-packages/logilab
	at sun.nio.fs.UnixException.translateToIOException(UnixException.java:84)
	at sun.nio.fs.UnixException.rethrowAsIOException(UnixException.java:102)
	at sun.nio.fs.UnixException.rethrowAsIOException(UnixException.java:107)
	at sun.nio.fs.UnixFileSystemProvider.newDirectoryStream(UnixFileSystemProvider.java:426)
	at java.nio.file.Files.newDirectoryStream(Files.java:411)
	at org.python.pydev.shared_core.io.FileUtils.getLastModifiedTimeFromDir(FileUtils.java:867)
	at org.python.pydev.shared_core.path_watch.EventsStackerRunnable.run(EventsStackerRunnable.java:217)
	at org.python.pydev.shared_core.path_watch.PathWatch$PollThread.run(PathWatch.java:193)

!ENTRY org.python.pydev.shared_core 4 4 2015-06-08 01:23:14.775
!MESSAGE /usr/lib/python2.7/site-packages/pylint
!STACK 0
java.nio.file.AccessDeniedException: /usr/lib/python2.7/site-packages/pylint
	at sun.nio.fs.UnixException.translateToIOException(UnixException.java:84)
	at sun.nio.fs.UnixException.rethrowAsIOException(UnixException.java:102)
	at sun.nio.fs.UnixException.rethrowAsIOException(UnixException.java:107)
	at sun.nio.fs.UnixFileSystemProvider.newDirectoryStream(UnixFileSystemProvider.java:426)
	at java.nio.file.Files.newDirectoryStream(Files.java:411)
	at org.python.pydev.shared_core.io.FileUtils.getLastModifiedTimeFromDir(FileUtils.java:867)
	at org.python.pydev.shared_core.path_watch.EventsStackerRunnable.run(EventsStackerRunnable.java:217)
	at org.python.pydev.shared_core.path_watch.PathWatch$PollThread.run(PathWatch.java:193)

!ENTRY org.eclipse.ui 2 2 2015-06-08 01:33:31.456
!MESSAGE Invalid preference category path: org.eclipse.mylyn.preferencePages.Mylyn (bundle: org.eclipse.mylyn.context.ui, page: org.eclipse.mylyn.context.ui.preferences)
